Workbook
Name holidays: Αργίες!$E$4:$E$63

Sheet Στοιχεία Πρακτικής
B2: Βιβλίο Πρακτικής Άσκησης Ασκούμενου | D2: v.2025-04-17
B5: Επώνυμο: | C5: Μελέτση
B6: Όνομα: | C6: Παρασκευή
B7: Σχολή: | C7: Τεχνολογιών Πληροφορικής και Επικοινωνιών
B8: Τμήμα: | C8: Ψηφιακών Συστημάτων
B9: Αριθ. Μητρώου: | C9: 3122067
B11: Φορέας Απασχόλησης
A12: 1 | B12: PricewaterhouseCoopers Business Solutions Α.Ε. | D12: επωνυμία
A13: 2 | B13: Λεωφ. Κηφισίας 268, 152 32 Χαλάνδρι | D13: διεύθυνση
A14: 3 | B14: +30 210 6874400 / pwc.greece@gr.pwc.com | D14: τηλέφωνο & email
B16: Επόπτης Απασχ/μενου
B17: Ονομ/νυμο: | C17: Τσίχλης Ηλίας
B18: Ιδιότητα: | C18: Engineering Manager / Staff Engineer
B20: Ημ/νία Έναρξης βάσει Σύμβασης: | C20: 46097 | D20: διαβάστε τα σχόλια του κελιού
B21: Δευτέρα Εβδομάδας Έναρξης: | C21: =C20-WEEKDAY(C20,2)+1
B22: Διάρκεια Πρακτικής σε Μήνες: | C22: 5.5
B23: Εκτίμηση ημερών εργασίας: | C23: =NETWORKDAYS(C20,C24,holidays)
B24: Ημ/νία Λήξης βάσει Σύμβασης: | C24: 46265 | D24: =C22 | E24: ημερολογιακοί μήνες
B29: Σύνολο Δηλωμένων Ημερών Απασχόλησης | C29: =extra!L69
B31: Για τις Πρακτικές των πρώην ΤΕΙ, η νομοθεσία απαιτεί 150 ένσημα πρακτικής άσκησης. Κάθε μήνας στις εργάσιμες μέρες του οποίου ο απασχολούμενος ήταν διαθέσιμος για εργασία, δίνει 25 ένσημα (παρά το γεγονός ότι οι εργάσιμες ενός μήνα είναι λιγότερες από 25!). Στο κελί παραπάνω, μετρώνται οι ημέρες πρακτικής άσκησης, με βάση τα δεδομένα στα υπόλοιπα φύλλα. Συνήθως αυτός ο αριθμός είναι γύρω στο 127 (συν πλην 2-3 μέρες) για 6-μηνες Πρακτικές πρώην ΤΕΙ.
B35: - Πανεπιστήμιο Πειραιώς -

Sheet 1ος
B1: ΕΒΔΟΜΑΔΙΑΙΟ ΦΥΛΛΟ ΠΡΑΚΤΙΚΗΣ ΑΣΚΗΣΗΣ
B3: ΕΒΔΟΜΑΔΑ | C3: από Δευτέρα: | D3: ='Στοιχεία Πρακτικής'!C21 | E3: =WEEKDAY(D3)
B4: 1 | C4: έως Παρασκευή: | D4: =D3+4 | E4: =WEEKDAY(D4)
B6: ΗΜΕΡΑ | C6: ΠΕΡΙΛΗΨΗ ΕΡΓΑΣΙΩΝ ΠΟΥ ΕΚΕΤΕΛΕΣΤΗΚΑΝ | D6: ΩΡΕΣ | F6: ΕΒΔΟΜΑΔΙΑΙΕΣ ΣΗΜΕΙΩΣΕΙΣ - ΠΑΡΑΤΗΡΗΣΕΙΣ ΑΣΚΟΥΜΕΝΟΥ
B7: =D3 | C7: Καλωσόρισμα στα γραφεία της PwC στην Αθήνα. Παροχή εξοπλισμού. | D7: 8
B8: =B7+1 | C8: Δεύτερη μέρα στα γραφεία της PwC. Συνάντηση με την ομάδα, Manager και Senior Software Engineer. | D8: 8
B9: =B8+1 | C9: Remote εργασία. Πέρασα τις αποδείξεις ως εξοδολόγια με τη βοήθεια του senior — μου εξήγησε πώς θα δουλεύω και με ποιες εφαρμογές. | D9: 8 | F9: Είχα ένα θερμό καλωσόρισμα από την ομάδα και την εταιρεία. Μου εξήγησαν αναλυτικά τι πρέπει να κάνω και με βοήθησαν να προσαρμοστώ. Έκανα μια αρχή σε βάση δεδομένων — εκπαιδευτικό, όχι πραγματικό έργο.
B10: =B9+1 | C10: 2 υποχρεωτικά online courses σχετικά με την εταιρεία και τις αρμοδιότητές μου (εκπαίδευση κανόνων και προσαρμογής). Εβδομαδιαίο meeting με την ομάδα του .NET. | D10: 8
B11: =B10+1 | C11: Visual Studio Subscription. GitHub Enterprise Cloud — ticket form Hub. SQL courses και σχεδιασμός βάσης δεδομένων για εκπαιδευτικό έργο σχολείων Αττικής (μη πραγματικό έργο). | D11: 8
C12: Σύνολο Εβδομαδιαίων Ωρών: | D12: =SUM(D7:D11)
C13: Ημέρες Εργασίας Εβδομάδας: | D13: =COUNTA(D7:D11) | K13: Σύνολο Εργάσιμων Ημερών: | L13: =D13
B15: ΕΒΔΟΜΑΔΙΑΙΟ ΦΥΛΛΟ ΠΡΑΚΤΙΚΗΣ ΑΣΚΗΣΗΣ
B17: ΕΒΔΟΜΑΔΑ | C17: από Δευτέρα: | D17: =D3+7 | E17: =D17
B18: =B4+1 | C18: έως Παρασκευή: | D18: =D17+4 | E18: =D18
B20: ΗΜΕΡΑ | C20: ΠΕΡΙΛΗΨΗ ΕΡΓΑΣΙΩΝ ΠΟΥ ΕΚΕΤΕΛΕΣΤΗΚΑΝ | D20: ΩΡΕΣ | F20: ΕΒΔΟΜΑΔΙΑΙΕΣ ΣΗΜΕΙΩΣΕΙΣ - ΠΑΡΑΤΗΡΗΣΕΙΣ ΑΣΚΟΥΜΕΝΟΥ
B21: =D17 | C21: Meeting με τον manager. Meeting με την ομάδα για απορίες. Συνέχεια της βάσης δεδομένων από την προηγούμενη εβδομάδα. | D21: 8
B22: =B21+1 | C22: Online eLearn με το HC. Cloud Platforms Interns sync — αναφορά εργασιών προηγούμενων ημερών. Διόρθωση βάσης δεδομένων μετά από συζήτηση με senior και manager. | D22: 8
B23: =B22+1 | C23: Αργία — 25η Μαρτίου (Εθνική Εορτή). | F23: Όλα εξελίσσονται ομαλά και ευχάριστα και συνεχίζω ό,τι μου είχε ανατεθεί.
B24: =B23+1 | C24: Meeting team .NET. Τελική διόρθωση και ολοκλήρωση του διαγράμματος ERD. Έναρξη δημιουργίας πινάκων σε MySQL / SQL Studio. | D24: 8
B25: =B24+1 | C25: Meeting team sync. Συνέχεια SQL και δημιουργία tickets στο IT για πρόσβαση σε εφαρμογές που θα χρειαστούν αργότερα. | D25: 8
C26: Σύνολο Εβδομαδιαίων Ωρών: | D26: =SUM(D21:D25)
C27: Ημέρες Εργασίας Εβδομάδας: | D27: =COUNTA(D21:D25) | K27: Σύνολο Εργάσιμων Ημερών: | L27: =D27+L13
B29: ΕΒΔΟΜΑΔΙΑΙΟ ΦΥΛΛΟ ΠΡΑΚΤΙΚΗΣ ΑΣΚΗΣΗΣ
B31: ΕΒΔΟΜΑΔΑ | C31: από Δευτέρα: | D31: =D17+7 | E31: =D31
B32: =B18+1 | C32: έως Παρασκευή: | D32: =D31+4 | E32: =D32
B34: ΗΜΕΡΑ | C34: ΠΕΡΙΛΗΨΗ ΕΡΓΑΣΙΩΝ ΠΟΥ ΕΚΕΤΕΛΕΣΤΗΚΑΝ | D34: ΩΡΕΣ | F34: ΕΒΔΟΜΑΔΙΑΙΕΣ ΣΗΜΕΙΩΣΕΙΣ - ΠΑΡΑΤΗΡΗΣΕΙΣ ΑΣΚΟΥΜΕΝΟΥ
B35: =D31 | C35: Meeting team. Meeting με τον manager. Συνέχεια SQL — ολοκλήρωση πινάκων και αποστολή στον senior για διόρθωση. Παρακολούθηση courses για React. | D35: 8
B36: =B35+1 | C36: Internship program meeting. Online courses από Udemy (React, frontend & backend) — υπόδειξη του manager. | D36: 8
B37: =B36+1 | C37: Meeting with team. Συνέχεια SQL: διόρθωση πινάκων μετά από παρατηρήσεις του senior. Ολοκλήρωση Database Assessment Part 1. Έναρξη Part 2 (25 queries σε Sakila DB) — κατέβασα τη βάση, την έτρεξα με τις οδηγίες και άρχισα να δημιουργώ τα queries. | D37: 8 | F37: Επικεντρώθηκα στην Database Assessment ώστε να την ολοκληρώσω. Part 1: ERD διάγραμμα και δημιουργία πινάκων σε MySQL. Part 2: Sakila database — απάντηση σε 25 queries.
B38: =B37+1 | C38: Meeting with team .NET. Συνέχεια του Part 2 της Database Assessment. Διόρθωση Part 1 μετά τις παρατηρήσεις του senior. | D38: 8
B39: =B38+1 | C39: Meeting with team. Συνέχεια Database Assessment Part 2. 2-ωρο ενημερωτικό meeting call με την εταιρεία. | D39: 8
C40: Σύνολο Εβδομαδιαίων Ωρών: | D40: =SUM(D35:D39)
C41: Ημέρες Εργασίας Εβδομάδας: | D41: =COUNTA(D35:D39) | K41: Σύνολο Εργάσιμων Ημερών: | L41: =D41+L27
B43: ΕΒΔΟΜΑΔΙΑΙΟ ΦΥΛΛΟ ΠΡΑΚΤΙΚΗΣ ΑΣΚΗΣΗΣ
B45: ΕΒΔΟΜΑΔΑ | C45: από Δευτέρα: | D45: =D31+7 | E45: =D45
B46: =B32+1 | C46: έως Παρασκευή: | D46: =D45+4 | E46: =D46
B48: ΗΜΕΡΑ | C48: ΠΕΡΙΛΗΨΗ ΕΡΓΑΣΙΩΝ ΠΟΥ ΕΚΕΤΕΛΕΣΤΗΚΑΝ | D48: ΩΡΕΣ | F48: ΕΒΔΟΜΑΔΙΑΙΕΣ ΣΗΜΕΙΩΣΕΙΣ - ΠΑΡΑΤΗΡΗΣΕΙΣ ΑΣΚΟΥΜΕΝΟΥ
B49: =D45 | C49: Meeting with team. Παράδοση Part 2 της Database Assessment στον senior για παρατηρήσεις. React courses. | D49: 8
B50: =B49+1 | C50: Meeting with manager. Cloud platform internship. Διορθώσεις στο Part 2 → ολοκλήρωση της Database Assessment. | D50: 8
B51: =B50+1 | C51: Meeting with team & .NET. Παρακολούθηση υποχρεωτικών AI courses (1/3). | D51: 8 | F51: Ολοκλήρωση της Database Assessment. Παρακολούθηση courses (AI & React).
...

Sheet 2ος
B1: ΕΒΔΟΜΑΔΙΑΙΟ ΦΥΛΛΟ ΠΡΑΚΤΙΚΗΣ ΑΣΚΗΣΗΣ
B3: ΕΒΔΟΜΑΔΑ | C3: από Δευτέρα: | D3: 46132 | E3: =D3
B4: =('2ος'!D3-'Στοιχεία Πρακτικής'!C21)/7 + 1 | C4: έως Παρασκευή: | D4: =D3+4 | E4: =D4
B6: ΗΜΕΡΑ | C6: ΠΕΡΙΛΗΨΗ ΕΡΓΑΣΙΩΝ ΠΟΥ ΕΚΕΤΕΛΕΣΤΗΚΑΝ | D6: ΩΡΕΣ | F6: ΕΒΔΟΜΑΔΙΑΙΕΣ ΣΗΜΕΙΩΣΕΙΣ - ΠΑΡΑΤΗΡΗΣΕΙΣ ΑΣΚΟΥΜΕΝΟΥ
B7: =D3 | C7: Course για τη React και τα API keys → ολοκλήρωση πρώτου course. Meeting with team and manager. | D7: 8
B8: =B7+1 | C8: Meeting Cloud platform internship. Έναρξη Web Calculator training — εμφάνιση UI σε React και βασικές λειτουργίες (+, −, ×, ÷). | D8: 8
B9: =B8+1 | C9: Meeting with team. Course για τη React (για να συνεχίσω το calculator). Αλλαγές στον calculator και συνέχεια του training. | D9: 8 | F9: Ξεκίνησα το Web Calculator training μετά την ολοκλήρωση των courses στη React.
B10: =B9+1 | C10: Meeting with team. AI use case series — ενημερωτικό από την εταιρεία. Συνέχεια του calculator — προσθήκη ιστορικού πράξεων. | D10: 8
B11: =B10+1 | C11: Meeting with team. Συνέχεια στο calculator history με καλύτερες τεχνικές. | D11: 8
C12: Σύνολο Εβδομαδιαίων Ωρών: | D12: =SUM(D7:D11)
C13: Ημέρες Εργασίας Εβδομάδας: | D13: =COUNTA(D7:D11) | K13: Σύνολο Εργάσιμων Ημερών: | L13: =D13+'1ος'!L69
B15: ΕΒΔΟΜΑΔΙΑΙΟ ΦΥΛΛΟ ΠΡΑΚΤΙΚΗΣ ΑΣΚΗΣΗΣ
B17: ΕΒΔΟΜΑΔΑ | C17: από Δευτέρα: | D17: =D3+7 | E17: =D17
B18: =B4+1 | C18: έως Παρασκευή: | D18: =D17+4 | E18: =D18
B20: ΗΜΕΡΑ | C20: ΠΕΡΙΛΗΨΗ ΕΡΓΑΣΙΩΝ ΠΟΥ ΕΚΕΤΕΛΕΣΤΗΚΑΝ | D20: ΩΡΕΣ | F20: ΕΒΔΟΜΑΔΙΑΙΕΣ ΣΗΜΕΙΩΣΕΙΣ - ΠΑΡΑΤΗΡΗΣΕΙΣ ΑΣΚΟΥΜΕΝΟΥ
B21: =D17
B22: =B21+1
B23: =B22+1
B24: =B23+1
B25: =B24+1
C26: Σύνολο Εβδομαδιαίων Ωρών: | D26: =SUM(D21:D25)
C27: Ημέρες Εργασίας Εβδομάδας: | D27: =COUNTA(D21:D25) | K27: Σύνολο Εργάσιμων Ημερών: | L27: =D27+L13
B29: ΕΒΔΟΜΑΔΙΑΙΟ ΦΥΛΛΟ ΠΡΑΚΤΙΚΗΣ ΑΣΚΗΣΗΣ
B31: ΕΒΔΟΜΑΔΑ | C31: από Δευτέρα: | D31: =D17+7 | E31: =D31
B32: =B18+1 | C32: έως Παρασκευή: | D32: =D31+4 | E32: =D32
B34: ΗΜΕΡΑ | C34: ΠΕΡΙΛΗΨΗ ΕΡΓΑΣΙΩΝ ΠΟΥ ΕΚΕΤΕΛΕΣΤΗΚΑΝ | D34: ΩΡΕΣ | F34: ΕΒΔΟΜΑΔΙΑΙΕΣ ΣΗΜΕΙΩΣΕΙΣ - ΠΑΡΑΤΗΡΗΣΕΙΣ ΑΣΚΟΥΜΕΝΟΥ
B35: =D31
B36: =B35+1
B37: =B36+1
B38: =B37+1
B39: =B38+1
C40: Σύνολο Εβδομαδιαίων Ωρών: | D40: =SUM(D35:D39)
C41: Ημέρες Εργασίας Εβδομάδας: | D41: =COUNTA(D35:D39) | K41: Σύνολο Εργάσιμων Ημερών: | L41: =D41+L27
B43: ΕΒΔΟΜΑΔΙΑΙΟ ΦΥΛΛΟ ΠΡΑΚΤΙΚΗΣ ΑΣΚΗΣΗΣ
B45: ΕΒΔΟΜΑΔΑ | C45: από Δευτέρα: | D45: =D31+7 | E45: =D45
B46: =B32+1 | C46: έως Παρασκευή: | D46: =D45+4 | E46: =D46
B48: ΗΜΕΡΑ | C48: ΠΕΡΙΛΗΨΗ ΕΡΓΑΣΙΩΝ ΠΟΥ ΕΚΕΤΕΛΕΣΤΗΚΑΝ | D48: ΩΡΕΣ | F48: ΕΒΔΟΜΑΔΙΑΙΕΣ ΣΗΜΕΙΩΣΕΙΣ - ΠΑΡΑΤΗΡΗΣΕΙΣ ΑΣΚΟΥΜΕΝΟΥ
B49: =D45
B50: =B49+1
B51: =B50+1
...

Sheet 3ος
B1: ΕΒΔΟΜΑΔΙΑΙΟ ΦΥΛΛΟ ΠΡΑΚΤΙΚΗΣ ΑΣΚΗΣΗΣ
B3: ΕΒΔΟΜΑΔΑ | C3: από Δευτέρα: | D3: 46167 | E3: =WEEKDAY(D3)
B4: =('3ος'!D3-'Στοιχεία Πρακτικής'!C21)/7 + 1 | C4: έως Παρασκευή: | D4: =D3+4 | E4: =WEEKDAY(D4)
B6: ΗΜΕΡΑ | C6: ΠΕΡΙΛΗΨΗ ΕΡΓΑΣΙΩΝ ΠΟΥ ΕΚΕΤΕΛΕΣΤΗΚΑΝ | D6: ΩΡΕΣ | F6: ΕΒΔΟΜΑΔΙΑΙΕΣ ΣΗΜΕΙΩΣΕΙΣ - ΠΑΡΑΤΗΡΗΣΕΙΣ ΑΣΚΟΥΜΕΝΟΥ
B7: =D3
B8: =B7+1
B9: =B8+1 | F9: ='1ος'!F9:M11
B10: =B9+1
B11: =B10+1
C12: Σύνολο Εβδομαδιαίων Ωρών: | D12: =SUM(D7:D11)
C13: Ημέρες Εργασίας Εβδομάδας: | D13: =COUNTA(D7:D11) | K13: Σύνολο Εργάσιμων Ημερών: | L13: =D13+'2ος'!L69
B15: ΕΒΔΟΜΑΔΙΑΙΟ ΦΥΛΛΟ ΠΡΑΚΤΙΚΗΣ ΑΣΚΗΣΗΣ
B17: ΕΒΔΟΜΑΔΑ | C17: από Δευτέρα: | D17: =D3+7 | E17: =D17
B18: =B4+1 | C18: έως Παρασκευή: | D18: =D17+4 | E18: =D18
B20: ΗΜΕΡΑ | C20: ΠΕΡΙΛΗΨΗ ΕΡΓΑΣΙΩΝ ΠΟΥ ΕΚΕΤΕΛΕΣΤΗΚΑΝ | D20: ΩΡΕΣ | F20: ΕΒΔΟΜΑΔΙΑΙΕΣ ΣΗΜΕΙΩΣΕΙΣ - ΠΑΡΑΤΗΡΗΣΕΙΣ ΑΣΚΟΥΜΕΝΟΥ
B21: =D17
B22: =B21+1
B23: =B22+1
B24: =B23+1
B25: =B24+1
C26: Σύνολο Εβδομαδιαίων Ωρών: | D26: =SUM(D21:D25)
C27: Ημέρες Εργασίας Εβδομάδας: | D27: =COUNTA(D21:D25) | K27: Σύνολο Εργάσιμων Ημερών: | L27: =D27+L13
B29: ΕΒΔΟΜΑΔΙΑΙΟ ΦΥΛΛΟ ΠΡΑΚΤΙΚΗΣ ΑΣΚΗΣΗΣ
B31: ΕΒΔΟΜΑΔΑ | C31: από Δευτέρα: | D31: =D17+7 | E31: =D31
B32: =B18+1 | C32: έως Παρασκευή: | D32: =D31+4 | E32: =D32
B34: ΗΜΕΡΑ | C34: ΠΕΡΙΛΗΨΗ ΕΡΓΑΣΙΩΝ ΠΟΥ ΕΚΕΤΕΛΕΣΤΗΚΑΝ | D34: ΩΡΕΣ | F34: ΕΒΔΟΜΑΔΙΑΙΕΣ ΣΗΜΕΙΩΣΕΙΣ - ΠΑΡΑΤΗΡΗΣΕΙΣ ΑΣΚΟΥΜΕΝΟΥ
B35: =D31
B36: =B35+1
B37: =B36+1
B38: =B37+1
B39: =B38+1
C40: Σύνολο Εβδομαδιαίων Ωρών: | D40: =SUM(D35:D39)
C41: Ημέρες Εργασίας Εβδομάδας: | D41: =COUNTA(D35:D39) | K41: Σύνολο Εργάσιμων Ημερών: | L41: =D41+L27
B43: ΕΒΔΟΜΑΔΙΑΙΟ ΦΥΛΛΟ ΠΡΑΚΤΙΚΗΣ ΑΣΚΗΣΗΣ
B45: ΕΒΔΟΜΑΔΑ | C45: από Δευτέρα: | D45: =D31+7 | E45: =D45
B46: =B32+1 | C46: έως Παρασκευή: | D46: =D45+4 | E46: =D46
B48: ΗΜΕΡΑ | C48: ΠΕΡΙΛΗΨΗ ΕΡΓΑΣΙΩΝ ΠΟΥ ΕΚΕΤΕΛΕΣΤΗΚΑΝ | D48: ΩΡΕΣ | F48: ΕΒΔΟΜΑΔΙΑΙΕΣ ΣΗΜΕΙΩΣΕΙΣ - ΠΑΡΑΤΗΡΗΣΕΙΣ ΑΣΚΟΥΜΕΝΟΥ
B49: =D45
B50: =B49+1
B51: =B50+1
...

Sheet 4ος
B1: ΕΒΔΟΜΑΔΙΑΙΟ ΦΥΛΛΟ ΠΡΑΚΤΙΚΗΣ ΑΣΚΗΣΗΣ
B3: ΕΒΔΟΜΑΔΑ | C3: από Δευτέρα: | D3: 46202 | E3: =WEEKDAY(D3)
B4: =('4ος'!D3-'Στοιχεία Πρακτικής'!C21)/7 + 1 | C4: έως Παρασκευή: | D4: =D3+4 | E4: =WEEKDAY(D4)
B6: ΗΜΕΡΑ | C6: ΠΕΡΙΛΗΨΗ ΕΡΓΑΣΙΩΝ ΠΟΥ ΕΚΕΤΕΛΕΣΤΗΚΑΝ | D6: ΩΡΕΣ | F6: ΕΒΔΟΜΑΔΙΑΙΕΣ ΣΗΜΕΙΩΣΕΙΣ - ΠΑΡΑΤΗΡΗΣΕΙΣ ΑΣΚΟΥΜΕΝΟΥ
B7: =D3
B8: =B7+1
B9: =B8+1 | F9: ='1ος'!F9:M11
B10: =B9+1
B11: =B10+1
C12: Σύνολο Εβδομαδιαίων Ωρών: | D12: =SUM(D7:D11)
C13: Ημέρες Εργασίας Εβδομάδας: | D13: =COUNTA(D7:D11) | K13: Σύνολο Εργάσιμων Ημερών: | L13: =D13+'3ος'!L69
B15: ΕΒΔΟΜΑΔΙΑΙΟ ΦΥΛΛΟ ΠΡΑΚΤΙΚΗΣ ΑΣΚΗΣΗΣ
B17: ΕΒΔΟΜΑΔΑ | C17: από Δευτέρα: | D17: =D3+7 | E17: =D17
B18: =B4+1 | C18: έως Παρασκευή: | D18: =D17+4 | E18: =D18
B20: ΗΜΕΡΑ | C20: ΠΕΡΙΛΗΨΗ ΕΡΓΑΣΙΩΝ ΠΟΥ ΕΚΕΤΕΛΕΣΤΗΚΑΝ | D20: ΩΡΕΣ | F20: ΕΒΔΟΜΑΔΙΑΙΕΣ ΣΗΜΕΙΩΣΕΙΣ - ΠΑΡΑΤΗΡΗΣΕΙΣ ΑΣΚΟΥΜΕΝΟΥ
B21: =D17
B22: =B21+1
B23: =B22+1
B24: =B23+1
B25: =B24+1
C26: Σύνολο Εβδομαδιαίων Ωρών: | D26: =SUM(D21:D25)
C27: Ημέρες Εργασίας Εβδομάδας: | D27: =COUNTA(D21:D25) | K27: Σύνολο Εργάσιμων Ημερών: | L27: =D27+L13
B29: ΕΒΔΟΜΑΔΙΑΙΟ ΦΥΛΛΟ ΠΡΑΚΤΙΚΗΣ ΑΣΚΗΣΗΣ
B31: ΕΒΔΟΜΑΔΑ | C31: από Δευτέρα: | D31: =D17+7 | E31: =D31
B32: =B18+1 | C32: έως Παρασκευή: | D32: =D31+4 | E32: =D32
B34: ΗΜΕΡΑ | C34: ΠΕΡΙΛΗΨΗ ΕΡΓΑΣΙΩΝ ΠΟΥ ΕΚΕΤΕΛΕΣΤΗΚΑΝ | D34: ΩΡΕΣ | F34: ΕΒΔΟΜΑΔΙΑΙΕΣ ΣΗΜΕΙΩΣΕΙΣ - ΠΑΡΑΤΗΡΗΣΕΙΣ ΑΣΚΟΥΜΕΝΟΥ
B35: =D31
B36: =B35+1
B37: =B36+1
B38: =B37+1
B39: =B38+1
C40: Σύνολο Εβδομαδιαίων Ωρών: | D40: =SUM(D35:D39)
C41: Ημέρες Εργασίας Εβδομάδας: | D41: =COUNTA(D35:D39) | K41: Σύνολο Εργάσιμων Ημερών: | L41: =D41+L27
B43: ΕΒΔΟΜΑΔΙΑΙΟ ΦΥΛΛΟ ΠΡΑΚΤΙΚΗΣ ΑΣΚΗΣΗΣ
B45: ΕΒΔΟΜΑΔΑ | C45: από Δευτέρα: | D45: =D31+7 | E45: =D45
B46: =B32+1 | C46: έως Παρασκευή: | D46: =D45+4 | E46: =D46
B48: ΗΜΕΡΑ | C48: ΠΕΡΙΛΗΨΗ ΕΡΓΑΣΙΩΝ ΠΟΥ ΕΚΕΤΕΛΕΣΤΗΚΑΝ | D48: ΩΡΕΣ | F48: ΕΒΔΟΜΑΔΙΑΙΕΣ ΣΗΜΕΙΩΣΕΙΣ - ΠΑΡΑΤΗΡΗΣΕΙΣ ΑΣΚΟΥΜΕΝΟΥ
B49: =D45
B50: =B49+1
B51: =B50+1
...

Sheet 5ος
B1: ΕΒΔΟΜΑΔΙΑΙΟ ΦΥΛΛΟ ΠΡΑΚΤΙΚΗΣ ΑΣΚΗΣΗΣ
B3: ΕΒΔΟΜΑΔΑ | C3: από Δευτέρα: | D3: 46237 | E3: =WEEKDAY(D3)
B4: =('5ος'!D3-'Στοιχεία Πρακτικής'!C21)/7 + 1 | C4: έως Παρασκευή: | D4: =D3+4 | E4: =WEEKDAY(D4)
B6: ΗΜΕΡΑ | C6: ΠΕΡΙΛΗΨΗ ΕΡΓΑΣΙΩΝ ΠΟΥ ΕΚΕΤΕΛΕΣΤΗΚΑΝ | D6: ΩΡΕΣ | F6: ΕΒΔΟΜΑΔΙΑΙΕΣ ΣΗΜΕΙΩΣΕΙΣ - ΠΑΡΑΤΗΡΗΣΕΙΣ ΑΣΚΟΥΜΕΝΟΥ
B7: =D3
B8: =B7+1
B9: =B8+1 | F9: ='1ος'!F9:M11
B10: =B9+1
B11: =B10+1
C12: Σύνολο Εβδομαδιαίων Ωρών: | D12: =SUM(D7:D11)
C13: Ημέρες Εργασίας Εβδομάδας: | D13: =COUNTA(D7:D11) | K13: Σύνολο Εργάσιμων Ημερών: | L13: =D13+'4ος'!L69
B15: ΕΒΔΟΜΑΔΙΑΙΟ ΦΥΛΛΟ ΠΡΑΚΤΙΚΗΣ ΑΣΚΗΣΗΣ
B17: ΕΒΔΟΜΑΔΑ | C17: από Δευτέρα: | D17: =D3+7 | E17: =D17
B18: =B4+1 | C18: έως Παρασκευή: | D18: =D17+4 | E18: =D18
B20: ΗΜΕΡΑ | C20: ΠΕΡΙΛΗΨΗ ΕΡΓΑΣΙΩΝ ΠΟΥ ΕΚΕΤΕΛΕΣΤΗΚΑΝ | D20: ΩΡΕΣ | F20: ΕΒΔΟΜΑΔΙΑΙΕΣ ΣΗΜΕΙΩΣΕΙΣ - ΠΑΡΑΤΗΡΗΣΕΙΣ ΑΣΚΟΥΜΕΝΟΥ
B21: =D17
B22: =B21+1
B23: =B22+1
B24: =B23+1
B25: =B24+1
C26: Σύνολο Εβδομαδιαίων Ωρών: | D26: =SUM(D21:D25)
C27: Ημέρες Εργασίας Εβδομάδας: | D27: =COUNTA(D21:D25) | K27: Σύνολο Εργάσιμων Ημερών: | L27: =D27+L13
B29: ΕΒΔΟΜΑΔΙΑΙΟ ΦΥΛΛΟ ΠΡΑΚΤΙΚΗΣ ΑΣΚΗΣΗΣ
B31: ΕΒΔΟΜΑΔΑ | C31: από Δευτέρα: | D31: =D17+7 | E31: =D31
B32: =B18+1 | C32: έως Παρασκευή: | D32: =D31+4 | E32: =D32
B34: ΗΜΕΡΑ | C34: ΠΕΡΙΛΗΨΗ ΕΡΓΑΣΙΩΝ ΠΟΥ ΕΚΕΤΕΛΕΣΤΗΚΑΝ | D34: ΩΡΕΣ | F34: ΕΒΔΟΜΑΔΙΑΙΕΣ ΣΗΜΕΙΩΣΕΙΣ - ΠΑΡΑΤΗΡΗΣΕΙΣ ΑΣΚΟΥΜΕΝΟΥ
B35: =D31
B36: =B35+1
B37: =B36+1
B38: =B37+1
B39: =B38+1
C40: Σύνολο Εβδομαδιαίων Ωρών: | D40: =SUM(D35:D39)
C41: Ημέρες Εργασίας Εβδομάδας: | D41: =COUNTA(D35:D39) | K41: Σύνολο Εργάσιμων Ημερών: | L41: =D41+L27
B43: ΕΒΔΟΜΑΔΙΑΙΟ ΦΥΛΛΟ ΠΡΑΚΤΙΚΗΣ ΑΣΚΗΣΗΣ
B45: ΕΒΔΟΜΑΔΑ | C45: από Δευτέρα: | D45: =D31+7 | E45: =D45
B46: =B32+1 | C46: έως Παρασκευή: | D46: =D45+4 | E46: =D46
B48: ΗΜΕΡΑ | C48: ΠΕΡΙΛΗΨΗ ΕΡΓΑΣΙΩΝ ΠΟΥ ΕΚΕΤΕΛΕΣΤΗΚΑΝ | D48: ΩΡΕΣ | F48: ΕΒΔΟΜΑΔΙΑΙΕΣ ΣΗΜΕΙΩΣΕΙΣ - ΠΑΡΑΤΗΡΗΣΕΙΣ ΑΣΚΟΥΜΕΝΟΥ
B49: =D45
B50: =B49+1
B51: =B50+1
...

Sheet 6ος

Sheet extra
B1: ΕΒΔΟΜΑΔΙΑΙΟ ΦΥΛΛΟ ΠΡΑΚΤΙΚΗΣ ΑΣΚΗΣΗΣ
B3: ΕΒΔΟΜΑΔΑ | C3: από Δευτέρα: | E3: =WEEKDAY(D3)
B4: =(extra!D3-'Στοιχεία Πρακτικής'!C21)/7 + 1 | C4: έως Παρασκευή: | D4: =D3+4 | E4: =WEEKDAY(D4)
B6: ΗΜΕΡΑ | C6: ΠΕΡΙΛΗΨΗ ΕΡΓΑΣΙΩΝ ΠΟΥ ΕΚΕΤΕΛΕΣΤΗΚΑΝ | D6: ΩΡΕΣ | F6: ΕΒΔΟΜΑΔΙΑΙΕΣ ΣΗΜΕΙΩΣΕΙΣ - ΠΑΡΑΤΗΡΗΣΕΙΣ ΑΣΚΟΥΜΕΝΟΥ
B7: =D3
B8: =B7+1
B9: =B8+1 | F9: ='1ος'!F9:M11
B10: =B9+1
B11: =B10+1
C12: Σύνολο Εβδομαδιαίων Ωρών: | D12: =SUM(D7:D11)
C13: Ημέρες Εργασίας Εβδομάδας: | D13: =COUNTA(D7:D11) | K13: Σύνολο Εργάσιμων Ημερών: | L13: =D13+'5ος'!L69
B15: ΕΒΔΟΜΑΔΙΑΙΟ ΦΥΛΛΟ ΠΡΑΚΤΙΚΗΣ ΑΣΚΗΣΗΣ
B17: ΕΒΔΟΜΑΔΑ | C17: από Δευτέρα: | D17: =D3+7 | E17: =D17
B18: =B4+1 | C18: έως Παρασκευή: | D18: =D17+4 | E18: =D18
B20: ΗΜΕΡΑ | C20: ΠΕΡΙΛΗΨΗ ΕΡΓΑΣΙΩΝ ΠΟΥ ΕΚΕΤΕΛΕΣΤΗΚΑΝ | D20: ΩΡΕΣ | F20: ΕΒΔΟΜΑΔΙΑΙΕΣ ΣΗΜΕΙΩΣΕΙΣ - ΠΑΡΑΤΗΡΗΣΕΙΣ ΑΣΚΟΥΜΕΝΟΥ
B21: =D17
B22: =B21+1
B23: =B22+1
B24: =B23+1
B25: =B24+1
C26: Σύνολο Εβδομαδιαίων Ωρών: | D26: =SUM(D21:D25)
C27: Ημέρες Εργασίας Εβδομάδας: | D27: =COUNTA(D21:D25) | K27: Σύνολο Εργάσιμων Ημερών: | L27: =D27+L13
B29: ΕΒΔΟΜΑΔΙΑΙΟ ΦΥΛΛΟ ΠΡΑΚΤΙΚΗΣ ΑΣΚΗΣΗΣ
B31: ΕΒΔΟΜΑΔΑ | C31: από Δευτέρα: | D31: =D17+7 | E31: =D31
B32: =B18+1 | C32: έως Παρασκευή: | D32: =D31+4 | E32: =D32
B34: ΗΜΕΡΑ | C34: ΠΕΡΙΛΗΨΗ ΕΡΓΑΣΙΩΝ ΠΟΥ ΕΚΕΤΕΛΕΣΤΗΚΑΝ | D34: ΩΡΕΣ | F34: ΕΒΔΟΜΑΔΙΑΙΕΣ ΣΗΜΕΙΩΣΕΙΣ - ΠΑΡΑΤΗΡΗΣΕΙΣ ΑΣΚΟΥΜΕΝΟΥ
B35: =D31
B36: =B35+1
B37: =B36+1
B38: =B37+1
B39: =B38+1
C40: Σύνολο Εβδομαδιαίων Ωρών: | D40: =SUM(D35:D39)
C41: Ημέρες Εργασίας Εβδομάδας: | D41: =COUNTA(D35:D39) | K41: Σύνολο Εργάσιμων Ημερών: | L41: =D41+L27
B43: ΕΒΔΟΜΑΔΙΑΙΟ ΦΥΛΛΟ ΠΡΑΚΤΙΚΗΣ ΑΣΚΗΣΗΣ
B45: ΕΒΔΟΜΑΔΑ | C45: από Δευτέρα: | D45: =D31+7 | E45: =D45
B46: =B32+1 | C46: έως Παρασκευή: | D46: =D45+4 | E46: =D46
B48: ΗΜΕΡΑ | C48: ΠΕΡΙΛΗΨΗ ΕΡΓΑΣΙΩΝ ΠΟΥ ΕΚΕΤΕΛΕΣΤΗΚΑΝ | D48: ΩΡΕΣ | F48: ΕΒΔΟΜΑΔΙΑΙΕΣ ΣΗΜΕΙΩΣΕΙΣ - ΠΑΡΑΤΗΡΗΣΕΙΣ ΑΣΚΟΥΜΕΝΟΥ
B49: =D45
B50: =B49+1
B51: =B50+1
...

Sheet ΑΠΟΛΟΓΙΣΜΟΣ
B1: ='Στοιχεία Πρακτικής'!C5 | F1: ='Στοιχεία Πρακτικής'!C6
B2: Απολογισμός Πρακτικής Άσκησης
B3: πρέπει να συμπληρωθεί υποχρεωτικά από τον ασκούμενο
B4: ΓΕΝΙΚΟΤΕΡΕΣ ΣΗΜΕΙΩΣΕΙΣ - ΠΑΡΑΤΗΡΗΣΕΙΣ ΤΟΥ ΑΣΚΟΥΜΕΝΟΥ ΓΙΑ ΤΙΣ ΕΡΓΑΣΙΑΚΕΣ ΕΜΠΕΙΡΙΕΣ
B25: Για αλλαγή παραγράφου μέσα στο κελί, πατήστε Alt+Enter
G27: (υπογραφή)
G28: ο ασκούμενος
B31: ΓΕΝΙΚΟΤΕΡΕΣ ΣΗΜΕΙΩΣΕΙΣ - ΠΑΡΑΤΗΡΗΣΕΙΣ ΕΠΟΠΤΗ ΕΚΑΙΔΕΥΤΙΚΟΥ (Προαιρετικό) ΑΞΙΟΛΟΓΗΣΗ ΠΡΑΚΤΙΚΗΣ ΑΣΚΗΣΗΣ
G45: ο επόπτης εκπ/κός

Sheet Αργίες
B3: Έτος | E3: Ημ/νία
B4: 2024 | C4: Σταθερές Αργίες | D4: Πρωτοχρονιάς | E4: =DATE(B4,1,1)
D5: Θεοφανείων | E5: =DATE(B4,1,6)
D6: 25ης Μαρτίου | E6: =DATE(B4,3,25)
D7: Πρωτομαγιάς | E7: =DATE(B4,5,1)
D8: Κοίμησης Θεοτόκου | E8: =DATE(B4,8,15)
D9: 28ης Οκτωβρίου | E9: =DATE(B4,10,28)
D10: Χριστουγέννων | E10: =DATE(B4,12,25)
D11: Σύναξης Θεοτόκου | E11: =DATE(B4,12,26)
C12: Άλλες Αργίες | D12: Καθαράς Δευτέρας | E12: 45369
D13: Μεγ. Παρασκευής | E13: 45415
D14: Μεγ. Σαββάτου | E14: =E13+1
D15: Κυριακής Πάσχα | E15: =E14+1
D16: Δευτέρας Πάσχα | E16: =E15+1
D17: Πεντηκοστής | E17: 45466
D18: Αγίου Πνεύματος | E18: 45467
D19: Άλλη αργία 1
D20: Άλλη αργία 2
D21: Άλλη αργία 3
D22: Άλλη αργία 4
D23: Άλλη αργία 5
B24: 2025 | C24: Σταθερές Αργίες | D24: Πρωτοχρονιάς | E24: =DATE(B24,1,1)
D25: Θεοφανείων | E25: =DATE(B24,1,6)
D26: 25ης Μαρτίου | E26: =DATE(B24,3,25)
D27: Πρωτομαγιάς | E27: =DATE(B24,5,1)
D28: Κοίμησης Θεοτόκου | E28: =DATE(B24,8,15)
D29: 28ης Οκτωβρίου | E29: =DATE(B24,10,28)
D30: Χριστουγέννων | E30: =DATE(B24,12,25)
D31: Σύναξης Θεοτόκου | E31: =DATE(B24,12,26)
C32: Άλλες Αργίες | D32: Καθαράς Δευτέρας | E32: 45719
D33: Μεγ. Παρασκευής | E33: 45765
D34: Μεγ. Σαββάτου | E34: =E33+1
D35: Κυριακής Πάσχα | E35: =E34+1
D36: Δευτέρας Πάσχα | E36: =E35+1
D37: Πεντηκοστής | E37: 45816
D38: Αγίου Πνεύματος | E38: =E37+1
D39: Άλλη αργία 1
D40: Άλλη αργία 2
D41: Άλλη αργία 3
D42: Άλλη αργία 4
...
